Wed, 17 Apr 2019 10:36:15 log.py[line:17] DEBUG 读取配置项发生了错误,mysql,host
Wed, 17 Apr 2019 10:36:15 log.py[line:20] ERROR No section: 'mysql'
Traceback (most recent call last):
  File "D:\soft\python36\lib\configparser.py", line 1138, in _unify_values
    sectiondict = self._sections[section]
KeyError: 'mysql'

During handling of the above exception, another exception occurred:

Traceback (most recent call last):
  File "E:\myproj\audit\common\config_reader.py", line 22, in get
    return self.conf.get(field,key)
  File "D:\soft\python36\lib\configparser.py", line 781, in get
    d = self._unify_values(section, vars)
  File "D:\soft\python36\lib\configparser.py", line 1141, in _unify_values
    raise NoSectionError(section)
configparser.NoSectionError: No section: 'mysql'
Wed, 17 Apr 2019 10:36:15 log.py[line:17] DEBUG 读取配置项发生了错误,mysql,port
Wed, 17 Apr 2019 10:36:15 log.py[line:20] ERROR No section: 'mysql'
Traceback (most recent call last):
  File "D:\soft\python36\lib\configparser.py", line 1138, in _unify_values
    sectiondict = self._sections[section]
KeyError: 'mysql'

During handling of the above exception, another exception occurred:

Traceback (most recent call last):
  File "E:\myproj\audit\common\config_reader.py", line 32, in getint
    return self.conf.getint(field,key)
  File "D:\soft\python36\lib\configparser.py", line 819, in getint
    fallback=fallback, **kwargs)
  File "D:\soft\python36\lib\configparser.py", line 809, in _get_conv
    **kwargs)
  File "D:\soft\python36\lib\configparser.py", line 803, in _get
    return conv(self.get(section, option, **kwargs))
  File "D:\soft\python36\lib\configparser.py", line 781, in get
    d = self._unify_values(section, vars)
  File "D:\soft\python36\lib\configparser.py", line 1141, in _unify_values
    raise NoSectionError(section)
configparser.NoSectionError: No section: 'mysql'
Wed, 17 Apr 2019 10:36:15 log.py[line:17] DEBUG 读取配置项发生了错误,mysql,username
Wed, 17 Apr 2019 10:36:15 log.py[line:20] ERROR No section: 'mysql'
Traceback (most recent call last):
  File "D:\soft\python36\lib\configparser.py", line 1138, in _unify_values
    sectiondict = self._sections[section]
KeyError: 'mysql'

During handling of the above exception, another exception occurred:

Traceback (most recent call last):
  File "E:\myproj\audit\common\config_reader.py", line 22, in get
    return self.conf.get(field,key)
  File "D:\soft\python36\lib\configparser.py", line 781, in get
    d = self._unify_values(section, vars)
  File "D:\soft\python36\lib\configparser.py", line 1141, in _unify_values
    raise NoSectionError(section)
configparser.NoSectionError: No section: 'mysql'
Wed, 17 Apr 2019 10:36:15 log.py[line:17] DEBUG 读取配置项发生了错误,mysql,passwd
Wed, 17 Apr 2019 10:36:15 log.py[line:20] ERROR No section: 'mysql'
Traceback (most recent call last):
  File "D:\soft\python36\lib\configparser.py", line 1138, in _unify_values
    sectiondict = self._sections[section]
KeyError: 'mysql'

During handling of the above exception, another exception occurred:

Traceback (most recent call last):
  File "E:\myproj\audit\common\config_reader.py", line 22, in get
    return self.conf.get(field,key)
  File "D:\soft\python36\lib\configparser.py", line 781, in get
    d = self._unify_values(section, vars)
  File "D:\soft\python36\lib\configparser.py", line 1141, in _unify_values
    raise NoSectionError(section)
configparser.NoSectionError: No section: 'mysql'
Wed, 17 Apr 2019 10:36:15 log.py[line:17] DEBUG 读取配置项发生了错误,mysql,dbname_sys
Wed, 17 Apr 2019 10:36:15 log.py[line:20] ERROR No section: 'mysql'
Traceback (most recent call last):
  File "D:\soft\python36\lib\configparser.py", line 1138, in _unify_values
    sectiondict = self._sections[section]
KeyError: 'mysql'

During handling of the above exception, another exception occurred:

Traceback (most recent call last):
  File "E:\myproj\audit\common\config_reader.py", line 22, in get
    return self.conf.get(field,key)
  File "D:\soft\python36\lib\configparser.py", line 781, in get
    d = self._unify_values(section, vars)
  File "D:\soft\python36\lib\configparser.py", line 1141, in _unify_values
    raise NoSectionError(section)
configparser.NoSectionError: No section: 'mysql'
Wed, 17 Apr 2019 10:36:15 log.py[line:17] DEBUG 读取配置项发生了错误,mysql,dbname_auditcenter
Wed, 17 Apr 2019 10:36:15 log.py[line:20] ERROR No section: 'mysql'
Traceback (most recent call last):
  File "D:\soft\python36\lib\configparser.py", line 1138, in _unify_values
    sectiondict = self._sections[section]
KeyError: 'mysql'

During handling of the above exception, another exception occurred:

Traceback (most recent call last):
  File "E:\myproj\audit\common\config_reader.py", line 22, in get
    return self.conf.get(field,key)
  File "D:\soft\python36\lib\configparser.py", line 781, in get
    d = self._unify_values(section, vars)
  File "D:\soft\python36\lib\configparser.py", line 1141, in _unify_values
    raise NoSectionError(section)
configparser.NoSectionError: No section: 'mysql'
Wed, 17 Apr 2019 10:36:15 log.py[line:17] DEBUG 读取配置项发生了错误,mysql,charset
Wed, 17 Apr 2019 10:36:15 log.py[line:20] ERROR No section: 'mysql'
Traceback (most recent call last):
  File "D:\soft\python36\lib\configparser.py", line 1138, in _unify_values
    sectiondict = self._sections[section]
KeyError: 'mysql'

During handling of the above exception, another exception occurred:

Traceback (most recent call last):
  File "E:\myproj\audit\common\config_reader.py", line 22, in get
    return self.conf.get(field,key)
  File "D:\soft\python36\lib\configparser.py", line 781, in get
    d = self._unify_values(section, vars)
  File "D:\soft\python36\lib\configparser.py", line 1141, in _unify_values
    raise NoSectionError(section)
configparser.NoSectionError: No section: 'mysql'
Wed, 17 Apr 2019 10:37:54 log.py[line:17] DEBUG 读取配置项发生了错误,mysql,host
Wed, 17 Apr 2019 10:37:54 log.py[line:20] ERROR No section: 'mysql'
Traceback (most recent call last):
  File "D:\soft\python36\lib\configparser.py", line 1138, in _unify_values
    sectiondict = self._sections[section]
KeyError: 'mysql'

During handling of the above exception, another exception occurred:

Traceback (most recent call last):
  File "E:\myproj\audit\common\config_reader.py", line 22, in get
    return self.conf.get(field,key)
  File "D:\soft\python36\lib\configparser.py", line 781, in get
    d = self._unify_values(section, vars)
  File "D:\soft\python36\lib\configparser.py", line 1141, in _unify_values
    raise NoSectionError(section)
configparser.NoSectionError: No section: 'mysql'
Wed, 17 Apr 2019 10:37:54 log.py[line:17] DEBUG 读取配置项发生了错误,mysql,port
Wed, 17 Apr 2019 10:37:54 log.py[line:20] ERROR No section: 'mysql'
Traceback (most recent call last):
  File "D:\soft\python36\lib\configparser.py", line 1138, in _unify_values
    sectiondict = self._sections[section]
KeyError: 'mysql'

During handling of the above exception, another exception occurred:

Traceback (most recent call last):
  File "E:\myproj\audit\common\config_reader.py", line 32, in getint
    return self.conf.getint(field,key)
  File "D:\soft\python36\lib\configparser.py", line 819, in getint
    fallback=fallback, **kwargs)
  File "D:\soft\python36\lib\configparser.py", line 809, in _get_conv
    **kwargs)
  File "D:\soft\python36\lib\configparser.py", line 803, in _get
    return conv(self.get(section, option, **kwargs))
  File "D:\soft\python36\lib\configparser.py", line 781, in get
    d = self._unify_values(section, vars)
  File "D:\soft\python36\lib\configparser.py", line 1141, in _unify_values
    raise NoSectionError(section)
configparser.NoSectionError: No section: 'mysql'
Wed, 17 Apr 2019 10:37:54 log.py[line:17] DEBUG 读取配置项发生了错误,mysql,username
Wed, 17 Apr 2019 10:37:54 log.py[line:20] ERROR No section: 'mysql'
Traceback (most recent call last):
  File "D:\soft\python36\lib\configparser.py", line 1138, in _unify_values
    sectiondict = self._sections[section]
KeyError: 'mysql'

During handling of the above exception, another exception occurred:

Traceback (most recent call last):
  File "E:\myproj\audit\common\config_reader.py", line 22, in get
    return self.conf.get(field,key)
  File "D:\soft\python36\lib\configparser.py", line 781, in get
    d = self._unify_values(section, vars)
  File "D:\soft\python36\lib\configparser.py", line 1141, in _unify_values
    raise NoSectionError(section)
configparser.NoSectionError: No section: 'mysql'
Wed, 17 Apr 2019 10:37:54 log.py[line:17] DEBUG 读取配置项发生了错误,mysql,passwd
Wed, 17 Apr 2019 10:37:54 log.py[line:20] ERROR No section: 'mysql'
Traceback (most recent call last):
  File "D:\soft\python36\lib\configparser.py", line 1138, in _unify_values
    sectiondict = self._sections[section]
KeyError: 'mysql'

During handling of the above exception, another exception occurred:

Traceback (most recent call last):
  File "E:\myproj\audit\common\config_reader.py", line 22, in get
    return self.conf.get(field,key)
  File "D:\soft\python36\lib\configparser.py", line 781, in get
    d = self._unify_values(section, vars)
  File "D:\soft\python36\lib\configparser.py", line 1141, in _unify_values
    raise NoSectionError(section)
configparser.NoSectionError: No section: 'mysql'
Wed, 17 Apr 2019 10:37:54 log.py[line:17] DEBUG 读取配置项发生了错误,mysql,dbname_sys
Wed, 17 Apr 2019 10:37:54 log.py[line:20] ERROR No section: 'mysql'
Traceback (most recent call last):
  File "D:\soft\python36\lib\configparser.py", line 1138, in _unify_values
    sectiondict = self._sections[section]
KeyError: 'mysql'

During handling of the above exception, another exception occurred:

Traceback (most recent call last):
  File "E:\myproj\audit\common\config_reader.py", line 22, in get
    return self.conf.get(field,key)
  File "D:\soft\python36\lib\configparser.py", line 781, in get
    d = self._unify_values(section, vars)
  File "D:\soft\python36\lib\configparser.py", line 1141, in _unify_values
    raise NoSectionError(section)
configparser.NoSectionError: No section: 'mysql'
Wed, 17 Apr 2019 10:37:54 log.py[line:17] DEBUG 读取配置项发生了错误,mysql,dbname_auditcenter
Wed, 17 Apr 2019 10:37:54 log.py[line:20] ERROR No section: 'mysql'
Traceback (most recent call last):
  File "D:\soft\python36\lib\configparser.py", line 1138, in _unify_values
    sectiondict = self._sections[section]
KeyError: 'mysql'

During handling of the above exception, another exception occurred:

Traceback (most recent call last):
  File "E:\myproj\audit\common\config_reader.py", line 22, in get
    return self.conf.get(field,key)
  File "D:\soft\python36\lib\configparser.py", line 781, in get
    d = self._unify_values(section, vars)
  File "D:\soft\python36\lib\configparser.py", line 1141, in _unify_values
    raise NoSectionError(section)
configparser.NoSectionError: No section: 'mysql'
Wed, 17 Apr 2019 10:37:54 log.py[line:17] DEBUG 读取配置项发生了错误,mysql,charset
Wed, 17 Apr 2019 10:37:54 log.py[line:20] ERROR No section: 'mysql'
Traceback (most recent call last):
  File "D:\soft\python36\lib\configparser.py", line 1138, in _unify_values
    sectiondict = self._sections[section]
KeyError: 'mysql'

During handling of the above exception, another exception occurred:

Traceback (most recent call last):
  File "E:\myproj\audit\common\config_reader.py", line 22, in get
    return self.conf.get(field,key)
  File "D:\soft\python36\lib\configparser.py", line 781, in get
    d = self._unify_values(section, vars)
  File "D:\soft\python36\lib\configparser.py", line 1141, in _unify_values
    raise NoSectionError(section)
configparser.NoSectionError: No section: 'mysql'
Wed, 17 Apr 2019 10:39:46 log.py[line:17] DEBUG 读取配置项发生了错误,mysql,host
Wed, 17 Apr 2019 10:39:49 log.py[line:20] ERROR No section: 'mysql'
Traceback (most recent call last):
  File "D:\soft\python36\lib\configparser.py", line 1138, in _unify_values
    sectiondict = self._sections[section]
KeyError: 'mysql'

During handling of the above exception, another exception occurred:

Traceback (most recent call last):
  File "E:\myproj\audit\common\config_reader.py", line 22, in get
    return self.conf.get(field,key)
  File "D:\soft\python36\lib\configparser.py", line 781, in get
    d = self._unify_values(section, vars)
  File "D:\soft\python36\lib\configparser.py", line 1141, in _unify_values
    raise NoSectionError(section)
configparser.NoSectionError: No section: 'mysql'
Wed, 17 Apr 2019 10:40:10 log.py[line:17] DEBUG 读取配置项发生了错误,mysql,port
Wed, 17 Apr 2019 10:40:41 log.py[line:17] DEBUG 读取配置项发生了错误,mysql,host
Wed, 17 Apr 2019 10:40:41 log.py[line:20] ERROR No section: 'mysql'
Traceback (most recent call last):
  File "D:\soft\python36\lib\configparser.py", line 1138, in _unify_values
    sectiondict = self._sections[section]
KeyError: 'mysql'

During handling of the above exception, another exception occurred:

Traceback (most recent call last):
  File "E:\myproj\audit\common\config_reader.py", line 22, in get
    return self.conf.get(field,key)
  File "D:\soft\python36\lib\configparser.py", line 781, in get
    d = self._unify_values(section, vars)
  File "D:\soft\python36\lib\configparser.py", line 1141, in _unify_values
    raise NoSectionError(section)
configparser.NoSectionError: No section: 'mysql'
Wed, 17 Apr 2019 10:40:41 log.py[line:17] DEBUG 读取配置项发生了错误,mysql,port
Wed, 17 Apr 2019 10:40:41 log.py[line:20] ERROR No section: 'mysql'
Traceback (most recent call last):
  File "D:\soft\python36\lib\configparser.py", line 1138, in _unify_values
    sectiondict = self._sections[section]
KeyError: 'mysql'

During handling of the above exception, another exception occurred:

Traceback (most recent call last):
  File "E:\myproj\audit\common\config_reader.py", line 32, in getint
    return self.conf.getint(field,key)
  File "D:\soft\python36\lib\configparser.py", line 819, in getint
    fallback=fallback, **kwargs)
  File "D:\soft\python36\lib\configparser.py", line 809, in _get_conv
    **kwargs)
  File "D:\soft\python36\lib\configparser.py", line 803, in _get
    return conv(self.get(section, option, **kwargs))
  File "D:\soft\python36\lib\configparser.py", line 781, in get
    d = self._unify_values(section, vars)
  File "D:\soft\python36\lib\configparser.py", line 1141, in _unify_values
    raise NoSectionError(section)
configparser.NoSectionError: No section: 'mysql'
Wed, 17 Apr 2019 10:40:41 log.py[line:17] DEBUG 读取配置项发生了错误,mysql,username
Wed, 17 Apr 2019 10:40:41 log.py[line:20] ERROR No section: 'mysql'
Traceback (most recent call last):
  File "D:\soft\python36\lib\configparser.py", line 1138, in _unify_values
    sectiondict = self._sections[section]
KeyError: 'mysql'

During handling of the above exception, another exception occurred:

Traceback (most recent call last):
  File "E:\myproj\audit\common\config_reader.py", line 22, in get
    return self.conf.get(field,key)
  File "D:\soft\python36\lib\configparser.py", line 781, in get
    d = self._unify_values(section, vars)
  File "D:\soft\python36\lib\configparser.py", line 1141, in _unify_values
    raise NoSectionError(section)
configparser.NoSectionError: No section: 'mysql'
Wed, 17 Apr 2019 10:40:41 log.py[line:17] DEBUG 读取配置项发生了错误,mysql,passwd
Wed, 17 Apr 2019 10:40:41 log.py[line:20] ERROR No section: 'mysql'
Traceback (most recent call last):
  File "D:\soft\python36\lib\configparser.py", line 1138, in _unify_values
    sectiondict = self._sections[section]
KeyError: 'mysql'

During handling of the above exception, another exception occurred:

Traceback (most recent call last):
  File "E:\myproj\audit\common\config_reader.py", line 22, in get
    return self.conf.get(field,key)
  File "D:\soft\python36\lib\configparser.py", line 781, in get
    d = self._unify_values(section, vars)
  File "D:\soft\python36\lib\configparser.py", line 1141, in _unify_values
    raise NoSectionError(section)
configparser.NoSectionError: No section: 'mysql'
Wed, 17 Apr 2019 10:40:42 log.py[line:17] DEBUG 读取配置项发生了错误,mysql,dbname_sys
Wed, 17 Apr 2019 10:40:42 log.py[line:20] ERROR No section: 'mysql'
Traceback (most recent call last):
  File "D:\soft\python36\lib\configparser.py", line 1138, in _unify_values
    sectiondict = self._sections[section]
KeyError: 'mysql'

During handling of the above exception, another exception occurred:

Traceback (most recent call last):
  File "E:\myproj\audit\common\config_reader.py", line 22, in get
    return self.conf.get(field,key)
  File "D:\soft\python36\lib\configparser.py", line 781, in get
    d = self._unify_values(section, vars)
  File "D:\soft\python36\lib\configparser.py", line 1141, in _unify_values
    raise NoSectionError(section)
configparser.NoSectionError: No section: 'mysql'
Wed, 17 Apr 2019 10:40:42 log.py[line:17] DEBUG 读取配置项发生了错误,mysql,dbname_auditcenter
Wed, 17 Apr 2019 10:40:42 log.py[line:20] ERROR No section: 'mysql'
Traceback (most recent call last):
  File "D:\soft\python36\lib\configparser.py", line 1138, in _unify_values
    sectiondict = self._sections[section]
KeyError: 'mysql'

During handling of the above exception, another exception occurred:

Traceback (most recent call last):
  File "E:\myproj\audit\common\config_reader.py", line 22, in get
    return self.conf.get(field,key)
  File "D:\soft\python36\lib\configparser.py", line 781, in get
    d = self._unify_values(section, vars)
  File "D:\soft\python36\lib\configparser.py", line 1141, in _unify_values
    raise NoSectionError(section)
configparser.NoSectionError: No section: 'mysql'
Wed, 17 Apr 2019 10:40:42 log.py[line:17] DEBUG 读取配置项发生了错误,mysql,charset
Wed, 17 Apr 2019 10:40:42 log.py[line:20] ERROR No section: 'mysql'
Traceback (most recent call last):
  File "D:\soft\python36\lib\configparser.py", line 1138, in _unify_values
    sectiondict = self._sections[section]
KeyError: 'mysql'

During handling of the above exception, another exception occurred:

Traceback (most recent call last):
  File "E:\myproj\audit\common\config_reader.py", line 22, in get
    return self.conf.get(field,key)
  File "D:\soft\python36\lib\configparser.py", line 781, in get
    d = self._unify_values(section, vars)
  File "D:\soft\python36\lib\configparser.py", line 1141, in _unify_values
    raise NoSectionError(section)
configparser.NoSectionError: No section: 'mysql'
Wed, 17 Apr 2019 11:05:54 log.py[line:17] DEBUG 读取配置项发生了错误,mysql,host
Wed, 17 Apr 2019 11:05:54 log.py[line:20] ERROR No section: 'mysql'
Traceback (most recent call last):
  File "D:\soft\python36\lib\configparser.py", line 1138, in _unify_values
    sectiondict = self._sections[section]
KeyError: 'mysql'

During handling of the above exception, another exception occurred:

Traceback (most recent call last):
  File "E:\myproj\audit\common\config_reader.py", line 22, in get
    return self.conf.get(field,key)
  File "D:\soft\python36\lib\configparser.py", line 781, in get
    d = self._unify_values(section, vars)
  File "D:\soft\python36\lib\configparser.py", line 1141, in _unify_values
    raise NoSectionError(section)
configparser.NoSectionError: No section: 'mysql'
Wed, 17 Apr 2019 11:05:54 log.py[line:17] DEBUG 读取配置项发生了错误,mysql,port
Wed, 17 Apr 2019 11:05:54 log.py[line:20] ERROR No section: 'mysql'
Traceback (most recent call last):
  File "D:\soft\python36\lib\configparser.py", line 1138, in _unify_values
    sectiondict = self._sections[section]
KeyError: 'mysql'

During handling of the above exception, another exception occurred:

Traceback (most recent call last):
  File "E:\myproj\audit\common\config_reader.py", line 32, in getint
    return self.conf.getint(field,key)
  File "D:\soft\python36\lib\configparser.py", line 819, in getint
    fallback=fallback, **kwargs)
  File "D:\soft\python36\lib\configparser.py", line 809, in _get_conv
    **kwargs)
  File "D:\soft\python36\lib\configparser.py", line 803, in _get
    return conv(self.get(section, option, **kwargs))
  File "D:\soft\python36\lib\configparser.py", line 781, in get
    d = self._unify_values(section, vars)
  File "D:\soft\python36\lib\configparser.py", line 1141, in _unify_values
    raise NoSectionError(section)
configparser.NoSectionError: No section: 'mysql'
Wed, 17 Apr 2019 11:05:54 log.py[line:17] DEBUG 读取配置项发生了错误,mysql,username
Wed, 17 Apr 2019 11:05:54 log.py[line:20] ERROR No section: 'mysql'
Traceback (most recent call last):
  File "D:\soft\python36\lib\configparser.py", line 1138, in _unify_values
    sectiondict = self._sections[section]
KeyError: 'mysql'

During handling of the above exception, another exception occurred:

Traceback (most recent call last):
  File "E:\myproj\audit\common\config_reader.py", line 22, in get
    return self.conf.get(field,key)
  File "D:\soft\python36\lib\configparser.py", line 781, in get
    d = self._unify_values(section, vars)
  File "D:\soft\python36\lib\configparser.py", line 1141, in _unify_values
    raise NoSectionError(section)
configparser.NoSectionError: No section: 'mysql'
Wed, 17 Apr 2019 11:05:54 log.py[line:17] DEBUG 读取配置项发生了错误,mysql,passwd
Wed, 17 Apr 2019 11:05:54 log.py[line:20] ERROR No section: 'mysql'
Traceback (most recent call last):
  File "D:\soft\python36\lib\configparser.py", line 1138, in _unify_values
    sectiondict = self._sections[section]
KeyError: 'mysql'

During handling of the above exception, another exception occurred:

Traceback (most recent call last):
  File "E:\myproj\audit\common\config_reader.py", line 22, in get
    return self.conf.get(field,key)
  File "D:\soft\python36\lib\configparser.py", line 781, in get
    d = self._unify_values(section, vars)
  File "D:\soft\python36\lib\configparser.py", line 1141, in _unify_values
    raise NoSectionError(section)
configparser.NoSectionError: No section: 'mysql'
Wed, 17 Apr 2019 11:05:54 log.py[line:17] DEBUG 读取配置项发生了错误,mysql,dbname_sys
Wed, 17 Apr 2019 11:05:54 log.py[line:20] ERROR No section: 'mysql'
Traceback (most recent call last):
  File "D:\soft\python36\lib\configparser.py", line 1138, in _unify_values
    sectiondict = self._sections[section]
KeyError: 'mysql'

During handling of the above exception, another exception occurred:

Traceback (most recent call last):
  File "E:\myproj\audit\common\config_reader.py", line 22, in get
    return self.conf.get(field,key)
  File "D:\soft\python36\lib\configparser.py", line 781, in get
    d = self._unify_values(section, vars)
  File "D:\soft\python36\lib\configparser.py", line 1141, in _unify_values
    raise NoSectionError(section)
configparser.NoSectionError: No section: 'mysql'
Wed, 17 Apr 2019 11:05:54 log.py[line:17] DEBUG 读取配置项发生了错误,mysql,dbname_auditcenter
Wed, 17 Apr 2019 11:05:54 log.py[line:20] ERROR No section: 'mysql'
Traceback (most recent call last):
  File "D:\soft\python36\lib\configparser.py", line 1138, in _unify_values
    sectiondict = self._sections[section]
KeyError: 'mysql'

During handling of the above exception, another exception occurred:

Traceback (most recent call last):
  File "E:\myproj\audit\common\config_reader.py", line 22, in get
    return self.conf.get(field,key)
  File "D:\soft\python36\lib\configparser.py", line 781, in get
    d = self._unify_values(section, vars)
  File "D:\soft\python36\lib\configparser.py", line 1141, in _unify_values
    raise NoSectionError(section)
configparser.NoSectionError: No section: 'mysql'
Wed, 17 Apr 2019 11:05:54 log.py[line:17] DEBUG 读取配置项发生了错误,mysql,charset
Wed, 17 Apr 2019 11:05:54 log.py[line:20] ERROR No section: 'mysql'
Traceback (most recent call last):
  File "D:\soft\python36\lib\configparser.py", line 1138, in _unify_values
    sectiondict = self._sections[section]
KeyError: 'mysql'

During handling of the above exception, another exception occurred:

Traceback (most recent call last):
  File "E:\myproj\audit\common\config_reader.py", line 22, in get
    return self.conf.get(field,key)
  File "D:\soft\python36\lib\configparser.py", line 781, in get
    d = self._unify_values(section, vars)
  File "D:\soft\python36\lib\configparser.py", line 1141, in _unify_values
    raise NoSectionError(section)
configparser.NoSectionError: No section: 'mysql'
