Thu, 18 Apr 2019 09:37:23 log.py[line:17] DEBUG 读取配置项发生了错误,projectsql,disAuditCount
Thu, 18 Apr 2019 09:37:23 log.py[line:20] ERROR No option 'disauditcount' in section: 'projectsql'
Traceback (most recent call last):
  File "D:\soft\python36\lib\configparser.py", line 789, in get
    value = d[option]
  File "D:\soft\python36\lib\collections\__init__.py", line 885, in __getitem__
    return self.__missing__(key)            # support subclasses that define __missing__
  File "D:\soft\python36\lib\collections\__init__.py", line 877, in __missing__
    raise KeyError(key)
KeyError: 'disauditcount'

During handling of the above exception, another exception occurred:

Traceback (most recent call last):
  File "E:\myproj\audit\common\config_reader.py", line 22, in get
    return self.conf.get(field,key)
  File "D:\soft\python36\lib\configparser.py", line 792, in get
    raise NoOptionError(option, section)
configparser.NoOptionError: No option 'disauditcount' in section: 'projectsql'
Thu, 18 Apr 2019 09:37:57 log.py[line:17] DEBUG 读取配置项发生了错误,projectsql,disAuditCount
Thu, 18 Apr 2019 09:37:57 log.py[line:20] ERROR No option 'disauditcount' in section: 'projectsql'
Traceback (most recent call last):
  File "D:\soft\python36\lib\configparser.py", line 789, in get
    value = d[option]
  File "D:\soft\python36\lib\collections\__init__.py", line 885, in __getitem__
    return self.__missing__(key)            # support subclasses that define __missing__
  File "D:\soft\python36\lib\collections\__init__.py", line 877, in __missing__
    raise KeyError(key)
KeyError: 'disauditcount'

During handling of the above exception, another exception occurred:

Traceback (most recent call last):
  File "E:\myproj\audit\common\config_reader.py", line 22, in get
    return self.conf.get(field,key)
  File "D:\soft\python36\lib\configparser.py", line 792, in get
    raise NoOptionError(option, section)
configparser.NoOptionError: No option 'disauditcount' in section: 'projectsql'
Thu, 18 Apr 2019 09:38:20 log.py[line:17] DEBUG 读取配置项发生了错误,projectsql,disAuditCount
Thu, 18 Apr 2019 09:38:20 log.py[line:20] ERROR No option 'disauditcount' in section: 'projectsql'
Traceback (most recent call last):
  File "D:\soft\python36\lib\configparser.py", line 789, in get
    value = d[option]
  File "D:\soft\python36\lib\collections\__init__.py", line 885, in __getitem__
    return self.__missing__(key)            # support subclasses that define __missing__
  File "D:\soft\python36\lib\collections\__init__.py", line 877, in __missing__
    raise KeyError(key)
KeyError: 'disauditcount'

During handling of the above exception, another exception occurred:

Traceback (most recent call last):
  File "E:\myproj\audit\common\config_reader.py", line 22, in get
    return self.conf.get(field,key)
  File "D:\soft\python36\lib\configparser.py", line 792, in get
    raise NoOptionError(option, section)
configparser.NoOptionError: No option 'disauditcount' in section: 'projectsql'
Thu, 18 Apr 2019 10:00:38 log.py[line:17] DEBUG 读取配置项发生了错误,ipt_workReportByOrg
Thu, 18 Apr 2019 10:00:38 log.py[line:20] ERROR No section: 'zone'
Traceback (most recent call last):
  File "D:\soft\python36\lib\configparser.py", line 846, in items
    d.update(self._sections[section])
KeyError: 'zone'

During handling of the above exception, another exception occurred:

Traceback (most recent call last):
  File "E:\myproj\audit\common\config_reader.py", line 43, in getitems
    defaultvalue=self.conf.items('zone')
  File "D:\soft\python36\lib\configparser.py", line 849, in items
    raise NoSectionError(section)
configparser.NoSectionError: No section: 'zone'
Thu, 18 Apr 2019 10:02:25 log.py[line:17] DEBUG 读取配置项发生了错误,ipt_workReportByOrg
Thu, 18 Apr 2019 10:02:25 log.py[line:20] ERROR No section: 'zone'
Traceback (most recent call last):
  File "D:\soft\python36\lib\configparser.py", line 846, in items
    d.update(self._sections[section])
KeyError: 'zone'

During handling of the above exception, another exception occurred:

Traceback (most recent call last):
  File "E:\myproj\audit\common\config_reader.py", line 43, in getitems
    defaultvalue=self.conf.items('zone')
  File "D:\soft\python36\lib\configparser.py", line 849, in items
    raise NoSectionError(section)
configparser.NoSectionError: No section: 'zone'
Thu, 18 Apr 2019 10:15:51 log.py[line:17] DEBUG 读取配置项发生了错误,mysql,dbname_sys
Thu, 18 Apr 2019 10:15:51 log.py[line:20] ERROR No option 'dbname_sys' in section: 'mysql'
Traceback (most recent call last):
  File "D:\soft\python36\lib\configparser.py", line 789, in get
    value = d[option]
  File "D:\soft\python36\lib\collections\__init__.py", line 885, in __getitem__
    return self.__missing__(key)            # support subclasses that define __missing__
  File "D:\soft\python36\lib\collections\__init__.py", line 877, in __missing__
    raise KeyError(key)
KeyError: 'dbname_sys'

During handling of the above exception, another exception occurred:

Traceback (most recent call last):
  File "E:\myproj\audit\common\config_reader.py", line 22, in get
    return self.conf.get(field,key)
  File "D:\soft\python36\lib\configparser.py", line 792, in get
    raise NoOptionError(option, section)
configparser.NoOptionError: No option 'dbname_sys' in section: 'mysql'
Thu, 18 Apr 2019 10:15:51 log.py[line:17] DEBUG 读取配置项发生了错误,mysql,dbname_sys
Thu, 18 Apr 2019 10:15:51 log.py[line:20] ERROR No option 'dbname_sys' in section: 'mysql'
Traceback (most recent call last):
  File "D:\soft\python36\lib\configparser.py", line 789, in get
    value = d[option]
  File "D:\soft\python36\lib\collections\__init__.py", line 885, in __getitem__
    return self.__missing__(key)            # support subclasses that define __missing__
  File "D:\soft\python36\lib\collections\__init__.py", line 877, in __missing__
    raise KeyError(key)
KeyError: 'dbname_sys'

During handling of the above exception, another exception occurred:

Traceback (most recent call last):
  File "E:\myproj\audit\common\config_reader.py", line 22, in get
    return self.conf.get(field,key)
  File "D:\soft\python36\lib\configparser.py", line 792, in get
    raise NoOptionError(option, section)
configparser.NoOptionError: No option 'dbname_sys' in section: 'mysql'
Thu, 18 Apr 2019 10:20:09 log.py[line:17] DEBUG 读取配置项发生了错误,mysql,dbname_sys
Thu, 18 Apr 2019 10:20:09 log.py[line:20] ERROR No option 'dbname_sys' in section: 'mysql'
Traceback (most recent call last):
  File "D:\soft\python36\lib\configparser.py", line 789, in get
    value = d[option]
  File "D:\soft\python36\lib\collections\__init__.py", line 885, in __getitem__
    return self.__missing__(key)            # support subclasses that define __missing__
  File "D:\soft\python36\lib\collections\__init__.py", line 877, in __missing__
    raise KeyError(key)
KeyError: 'dbname_sys'

During handling of the above exception, another exception occurred:

Traceback (most recent call last):
  File "E:\myproj\audit\common\config_reader.py", line 22, in get
    return self.conf.get(field,key)
  File "D:\soft\python36\lib\configparser.py", line 792, in get
    raise NoOptionError(option, section)
configparser.NoOptionError: No option 'dbname_sys' in section: 'mysql'
Thu, 18 Apr 2019 10:20:10 log.py[line:17] DEBUG 读取配置项发生了错误,mysql,dbname_sys
Thu, 18 Apr 2019 10:20:10 log.py[line:20] ERROR No option 'dbname_sys' in section: 'mysql'
Traceback (most recent call last):
  File "D:\soft\python36\lib\configparser.py", line 789, in get
    value = d[option]
  File "D:\soft\python36\lib\collections\__init__.py", line 885, in __getitem__
    return self.__missing__(key)            # support subclasses that define __missing__
  File "D:\soft\python36\lib\collections\__init__.py", line 877, in __missing__
    raise KeyError(key)
KeyError: 'dbname_sys'

During handling of the above exception, another exception occurred:

Traceback (most recent call last):
  File "E:\myproj\audit\common\config_reader.py", line 22, in get
    return self.conf.get(field,key)
  File "D:\soft\python36\lib\configparser.py", line 792, in get
    raise NoOptionError(option, section)
configparser.NoOptionError: No option 'dbname_sys' in section: 'mysql'
Thu, 18 Apr 2019 10:20:43 log.py[line:17] DEBUG 读取配置项发生了错误,mysql,dbname_sys
Thu, 18 Apr 2019 10:20:43 log.py[line:20] ERROR No option 'dbname_sys' in section: 'mysql'
Traceback (most recent call last):
  File "D:\soft\python36\lib\configparser.py", line 789, in get
    value = d[option]
  File "D:\soft\python36\lib\collections\__init__.py", line 885, in __getitem__
    return self.__missing__(key)            # support subclasses that define __missing__
  File "D:\soft\python36\lib\collections\__init__.py", line 877, in __missing__
    raise KeyError(key)
KeyError: 'dbname_sys'

During handling of the above exception, another exception occurred:

Traceback (most recent call last):
  File "E:\myproj\audit\common\config_reader.py", line 22, in get
    return self.conf.get(field,key)
  File "D:\soft\python36\lib\configparser.py", line 792, in get
    raise NoOptionError(option, section)
configparser.NoOptionError: No option 'dbname_sys' in section: 'mysql'
Thu, 18 Apr 2019 10:20:43 log.py[line:17] DEBUG 读取配置项发生了错误,mysql,dbname_sys
Thu, 18 Apr 2019 10:20:43 log.py[line:20] ERROR No option 'dbname_sys' in section: 'mysql'
Traceback (most recent call last):
  File "D:\soft\python36\lib\configparser.py", line 789, in get
    value = d[option]
  File "D:\soft\python36\lib\collections\__init__.py", line 885, in __getitem__
    return self.__missing__(key)            # support subclasses that define __missing__
  File "D:\soft\python36\lib\collections\__init__.py", line 877, in __missing__
    raise KeyError(key)
KeyError: 'dbname_sys'

During handling of the above exception, another exception occurred:

Traceback (most recent call last):
  File "E:\myproj\audit\common\config_reader.py", line 22, in get
    return self.conf.get(field,key)
  File "D:\soft\python36\lib\configparser.py", line 792, in get
    raise NoOptionError(option, section)
configparser.NoOptionError: No option 'dbname_sys' in section: 'mysql'
Thu, 18 Apr 2019 10:30:22 log.py[line:17] DEBUG 读取配置项发生了错误,mysql,dbname_sys
Thu, 18 Apr 2019 10:30:22 log.py[line:20] ERROR No option 'dbname_sys' in section: 'mysql'
Traceback (most recent call last):
  File "D:\soft\python36\lib\configparser.py", line 789, in get
    value = d[option]
  File "D:\soft\python36\lib\collections\__init__.py", line 885, in __getitem__
    return self.__missing__(key)            # support subclasses that define __missing__
  File "D:\soft\python36\lib\collections\__init__.py", line 877, in __missing__
    raise KeyError(key)
KeyError: 'dbname_sys'

During handling of the above exception, another exception occurred:

Traceback (most recent call last):
  File "E:\myproj\audit\common\config_reader.py", line 22, in get
    return self.conf.get(field,key)
  File "D:\soft\python36\lib\configparser.py", line 792, in get
    raise NoOptionError(option, section)
configparser.NoOptionError: No option 'dbname_sys' in section: 'mysql'
Thu, 18 Apr 2019 10:30:22 log.py[line:17] DEBUG 读取配置项发生了错误,mysql,dbname_sys
Thu, 18 Apr 2019 10:30:22 log.py[line:20] ERROR No option 'dbname_sys' in section: 'mysql'
Traceback (most recent call last):
  File "D:\soft\python36\lib\configparser.py", line 789, in get
    value = d[option]
  File "D:\soft\python36\lib\collections\__init__.py", line 885, in __getitem__
    return self.__missing__(key)            # support subclasses that define __missing__
  File "D:\soft\python36\lib\collections\__init__.py", line 877, in __missing__
    raise KeyError(key)
KeyError: 'dbname_sys'

During handling of the above exception, another exception occurred:

Traceback (most recent call last):
  File "E:\myproj\audit\common\config_reader.py", line 22, in get
    return self.conf.get(field,key)
  File "D:\soft\python36\lib\configparser.py", line 792, in get
    raise NoOptionError(option, section)
configparser.NoOptionError: No option 'dbname_sys' in section: 'mysql'
Thu, 18 Apr 2019 10:30:44 log.py[line:17] DEBUG 读取配置项发生了错误,mysql,dbname_sys
Thu, 18 Apr 2019 10:30:44 log.py[line:20] ERROR No option 'dbname_sys' in section: 'mysql'
Traceback (most recent call last):
  File "D:\soft\python36\lib\configparser.py", line 789, in get
    value = d[option]
  File "D:\soft\python36\lib\collections\__init__.py", line 885, in __getitem__
    return self.__missing__(key)            # support subclasses that define __missing__
  File "D:\soft\python36\lib\collections\__init__.py", line 877, in __missing__
    raise KeyError(key)
KeyError: 'dbname_sys'

During handling of the above exception, another exception occurred:

Traceback (most recent call last):
  File "E:\myproj\audit\common\config_reader.py", line 22, in get
    return self.conf.get(field,key)
  File "D:\soft\python36\lib\configparser.py", line 792, in get
    raise NoOptionError(option, section)
configparser.NoOptionError: No option 'dbname_sys' in section: 'mysql'
Thu, 18 Apr 2019 10:30:44 log.py[line:17] DEBUG 读取配置项发生了错误,mysql,dbname_sys
Thu, 18 Apr 2019 10:30:44 log.py[line:20] ERROR No option 'dbname_sys' in section: 'mysql'
Traceback (most recent call last):
  File "D:\soft\python36\lib\configparser.py", line 789, in get
    value = d[option]
  File "D:\soft\python36\lib\collections\__init__.py", line 885, in __getitem__
    return self.__missing__(key)            # support subclasses that define __missing__
  File "D:\soft\python36\lib\collections\__init__.py", line 877, in __missing__
    raise KeyError(key)
KeyError: 'dbname_sys'

During handling of the above exception, another exception occurred:

Traceback (most recent call last):
  File "E:\myproj\audit\common\config_reader.py", line 22, in get
    return self.conf.get(field,key)
  File "D:\soft\python36\lib\configparser.py", line 792, in get
    raise NoOptionError(option, section)
configparser.NoOptionError: No option 'dbname_sys' in section: 'mysql'
Thu, 18 Apr 2019 10:31:36 log.py[line:17] DEBUG 读取配置项发生了错误,mysql,dbname_sys
Thu, 18 Apr 2019 10:31:36 log.py[line:20] ERROR No option 'dbname_sys' in section: 'mysql'
Traceback (most recent call last):
  File "D:\soft\python36\lib\configparser.py", line 789, in get
    value = d[option]
  File "D:\soft\python36\lib\collections\__init__.py", line 885, in __getitem__
    return self.__missing__(key)            # support subclasses that define __missing__
  File "D:\soft\python36\lib\collections\__init__.py", line 877, in __missing__
    raise KeyError(key)
KeyError: 'dbname_sys'

During handling of the above exception, another exception occurred:

Traceback (most recent call last):
  File "E:\myproj\audit\common\config_reader.py", line 22, in get
    return self.conf.get(field,key)
  File "D:\soft\python36\lib\configparser.py", line 792, in get
    raise NoOptionError(option, section)
configparser.NoOptionError: No option 'dbname_sys' in section: 'mysql'
Thu, 18 Apr 2019 10:31:36 log.py[line:17] DEBUG 读取配置项发生了错误,mysql,dbname_sys
Thu, 18 Apr 2019 10:31:36 log.py[line:20] ERROR No option 'dbname_sys' in section: 'mysql'
Traceback (most recent call last):
  File "D:\soft\python36\lib\configparser.py", line 789, in get
    value = d[option]
  File "D:\soft\python36\lib\collections\__init__.py", line 885, in __getitem__
    return self.__missing__(key)            # support subclasses that define __missing__
  File "D:\soft\python36\lib\collections\__init__.py", line 877, in __missing__
    raise KeyError(key)
KeyError: 'dbname_sys'

During handling of the above exception, another exception occurred:

Traceback (most recent call last):
  File "E:\myproj\audit\common\config_reader.py", line 22, in get
    return self.conf.get(field,key)
  File "D:\soft\python36\lib\configparser.py", line 792, in get
    raise NoOptionError(option, section)
configparser.NoOptionError: No option 'dbname_sys' in section: 'mysql'
Thu, 18 Apr 2019 13:58:30 log.py[line:17] DEBUG 读取配置项发生了错误,mysql,dbname_sys
Thu, 18 Apr 2019 13:58:30 log.py[line:20] ERROR No option 'dbname_sys' in section: 'mysql'
Traceback (most recent call last):
  File "D:\soft\python36\lib\configparser.py", line 789, in get
    value = d[option]
  File "D:\soft\python36\lib\collections\__init__.py", line 885, in __getitem__
    return self.__missing__(key)            # support subclasses that define __missing__
  File "D:\soft\python36\lib\collections\__init__.py", line 877, in __missing__
    raise KeyError(key)
KeyError: 'dbname_sys'

During handling of the above exception, another exception occurred:

Traceback (most recent call last):
  File "E:\myproj\audit\common\config_reader.py", line 22, in get
    return self.conf.get(field,key)
  File "D:\soft\python36\lib\configparser.py", line 792, in get
    raise NoOptionError(option, section)
configparser.NoOptionError: No option 'dbname_sys' in section: 'mysql'
Thu, 18 Apr 2019 14:11:49 log.py[line:17] DEBUG 读取配置项发生了错误,mysql,dbname_sys
Thu, 18 Apr 2019 14:11:49 log.py[line:20] ERROR No option 'dbname_sys' in section: 'mysql'
Traceback (most recent call last):
  File "D:\soft\python36\lib\configparser.py", line 789, in get
    value = d[option]
  File "D:\soft\python36\lib\collections\__init__.py", line 885, in __getitem__
    return self.__missing__(key)            # support subclasses that define __missing__
  File "D:\soft\python36\lib\collections\__init__.py", line 877, in __missing__
    raise KeyError(key)
KeyError: 'dbname_sys'

During handling of the above exception, another exception occurred:

Traceback (most recent call last):
  File "E:\myproj\audit\common\config_reader.py", line 22, in get
    return self.conf.get(field,key)
  File "D:\soft\python36\lib\configparser.py", line 792, in get
    raise NoOptionError(option, section)
configparser.NoOptionError: No option 'dbname_sys' in section: 'mysql'
Thu, 18 Apr 2019 14:13:21 log.py[line:17] DEBUG 读取配置项发生了错误,mysql,dbname_sys
Thu, 18 Apr 2019 14:13:21 log.py[line:20] ERROR No option 'dbname_sys' in section: 'mysql'
Traceback (most recent call last):
  File "D:\soft\python36\lib\configparser.py", line 789, in get
    value = d[option]
  File "D:\soft\python36\lib\collections\__init__.py", line 885, in __getitem__
    return self.__missing__(key)            # support subclasses that define __missing__
  File "D:\soft\python36\lib\collections\__init__.py", line 877, in __missing__
    raise KeyError(key)
KeyError: 'dbname_sys'

During handling of the above exception, another exception occurred:

Traceback (most recent call last):
  File "E:\myproj\audit\common\config_reader.py", line 22, in get
    return self.conf.get(field,key)
  File "D:\soft\python36\lib\configparser.py", line 792, in get
    raise NoOptionError(option, section)
configparser.NoOptionError: No option 'dbname_sys' in section: 'mysql'
Thu, 18 Apr 2019 14:15:59 log.py[line:17] DEBUG 读取配置项发生了错误,mysql,dbname_sys
Thu, 18 Apr 2019 14:15:59 log.py[line:20] ERROR No option 'dbname_sys' in section: 'mysql'
Traceback (most recent call last):
  File "D:\soft\python36\lib\configparser.py", line 789, in get
    value = d[option]
  File "D:\soft\python36\lib\collections\__init__.py", line 885, in __getitem__
    return self.__missing__(key)            # support subclasses that define __missing__
  File "D:\soft\python36\lib\collections\__init__.py", line 877, in __missing__
    raise KeyError(key)
KeyError: 'dbname_sys'

During handling of the above exception, another exception occurred:

Traceback (most recent call last):
  File "E:\myproj\audit\common\config_reader.py", line 22, in get
    return self.conf.get(field,key)
  File "D:\soft\python36\lib\configparser.py", line 792, in get
    raise NoOptionError(option, section)
configparser.NoOptionError: No option 'dbname_sys' in section: 'mysql'
Thu, 18 Apr 2019 14:17:18 log.py[line:17] DEBUG 读取配置项发生了错误,mysql,dbname_sys
Thu, 18 Apr 2019 14:17:18 log.py[line:20] ERROR No option 'dbname_sys' in section: 'mysql'
Traceback (most recent call last):
  File "D:\soft\python36\lib\configparser.py", line 789, in get
    value = d[option]
  File "D:\soft\python36\lib\collections\__init__.py", line 885, in __getitem__
    return self.__missing__(key)            # support subclasses that define __missing__
  File "D:\soft\python36\lib\collections\__init__.py", line 877, in __missing__
    raise KeyError(key)
KeyError: 'dbname_sys'

During handling of the above exception, another exception occurred:

Traceback (most recent call last):
  File "E:\myproj\audit\common\config_reader.py", line 22, in get
    return self.conf.get(field,key)
  File "D:\soft\python36\lib\configparser.py", line 792, in get
    raise NoOptionError(option, section)
configparser.NoOptionError: No option 'dbname_sys' in section: 'mysql'
Thu, 18 Apr 2019 14:18:51 log.py[line:17] DEBUG 读取配置项发生了错误,mysql,dbname_sys
Thu, 18 Apr 2019 14:18:51 log.py[line:20] ERROR No option 'dbname_sys' in section: 'mysql'
Traceback (most recent call last):
  File "D:\soft\python36\lib\configparser.py", line 789, in get
    value = d[option]
  File "D:\soft\python36\lib\collections\__init__.py", line 885, in __getitem__
    return self.__missing__(key)            # support subclasses that define __missing__
  File "D:\soft\python36\lib\collections\__init__.py", line 877, in __missing__
    raise KeyError(key)
KeyError: 'dbname_sys'

During handling of the above exception, another exception occurred:

Traceback (most recent call last):
  File "E:\myproj\audit\common\config_reader.py", line 22, in get
    return self.conf.get(field,key)
  File "D:\soft\python36\lib\configparser.py", line 792, in get
    raise NoOptionError(option, section)
configparser.NoOptionError: No option 'dbname_sys' in section: 'mysql'
Thu, 18 Apr 2019 14:20:23 log.py[line:17] DEBUG 读取配置项发生了错误,mysql,dbname_sys
Thu, 18 Apr 2019 14:20:23 log.py[line:20] ERROR No option 'dbname_sys' in section: 'mysql'
Traceback (most recent call last):
  File "D:\soft\python36\lib\configparser.py", line 789, in get
    value = d[option]
  File "D:\soft\python36\lib\collections\__init__.py", line 885, in __getitem__
    return self.__missing__(key)            # support subclasses that define __missing__
  File "D:\soft\python36\lib\collections\__init__.py", line 877, in __missing__
    raise KeyError(key)
KeyError: 'dbname_sys'

During handling of the above exception, another exception occurred:

Traceback (most recent call last):
  File "E:\myproj\audit\common\config_reader.py", line 22, in get
    return self.conf.get(field,key)
  File "D:\soft\python36\lib\configparser.py", line 792, in get
    raise NoOptionError(option, section)
configparser.NoOptionError: No option 'dbname_sys' in section: 'mysql'
Thu, 18 Apr 2019 15:22:48 log.py[line:17] DEBUG 读取配置项发生了错误,mysql,dbname_sys
Thu, 18 Apr 2019 15:22:48 log.py[line:20] ERROR No option 'dbname_sys' in section: 'mysql'
Traceback (most recent call last):
  File "D:\soft\python36\lib\configparser.py", line 789, in get
    value = d[option]
  File "D:\soft\python36\lib\collections\__init__.py", line 885, in __getitem__
    return self.__missing__(key)            # support subclasses that define __missing__
  File "D:\soft\python36\lib\collections\__init__.py", line 877, in __missing__
    raise KeyError(key)
KeyError: 'dbname_sys'

During handling of the above exception, another exception occurred:

Traceback (most recent call last):
  File "E:\myproj\audit\common\config_reader.py", line 22, in get
    return self.conf.get(field,key)
  File "D:\soft\python36\lib\configparser.py", line 792, in get
    raise NoOptionError(option, section)
configparser.NoOptionError: No option 'dbname_sys' in section: 'mysql'
Thu, 18 Apr 2019 15:26:55 log.py[line:17] DEBUG 读取配置项发生了错误,mysql,dbname_sys
Thu, 18 Apr 2019 15:26:55 log.py[line:20] ERROR No option 'dbname_sys' in section: 'mysql'
Traceback (most recent call last):
  File "D:\soft\python36\lib\configparser.py", line 789, in get
    value = d[option]
  File "D:\soft\python36\lib\collections\__init__.py", line 885, in __getitem__
    return self.__missing__(key)            # support subclasses that define __missing__
  File "D:\soft\python36\lib\collections\__init__.py", line 877, in __missing__
    raise KeyError(key)
KeyError: 'dbname_sys'

During handling of the above exception, another exception occurred:

Traceback (most recent call last):
  File "E:\myproj\audit\common\config_reader.py", line 22, in get
    return self.conf.get(field,key)
  File "D:\soft\python36\lib\configparser.py", line 792, in get
    raise NoOptionError(option, section)
configparser.NoOptionError: No option 'dbname_sys' in section: 'mysql'
Thu, 18 Apr 2019 15:28:04 log.py[line:17] DEBUG 读取配置项发生了错误,mysql,dbname_sys
Thu, 18 Apr 2019 15:28:04 log.py[line:20] ERROR No option 'dbname_sys' in section: 'mysql'
Traceback (most recent call last):
  File "D:\soft\python36\lib\configparser.py", line 789, in get
    value = d[option]
  File "D:\soft\python36\lib\collections\__init__.py", line 885, in __getitem__
    return self.__missing__(key)            # support subclasses that define __missing__
  File "D:\soft\python36\lib\collections\__init__.py", line 877, in __missing__
    raise KeyError(key)
KeyError: 'dbname_sys'

During handling of the above exception, another exception occurred:

Traceback (most recent call last):
  File "E:\myproj\audit\common\config_reader.py", line 22, in get
    return self.conf.get(field,key)
  File "D:\soft\python36\lib\configparser.py", line 792, in get
    raise NoOptionError(option, section)
configparser.NoOptionError: No option 'dbname_sys' in section: 'mysql'
Thu, 18 Apr 2019 15:30:30 log.py[line:17] DEBUG 读取配置项发生了错误,mysql,dbname_sys
Thu, 18 Apr 2019 15:30:30 log.py[line:20] ERROR No option 'dbname_sys' in section: 'mysql'
Traceback (most recent call last):
  File "D:\soft\python36\lib\configparser.py", line 789, in get
    value = d[option]
  File "D:\soft\python36\lib\collections\__init__.py", line 885, in __getitem__
    return self.__missing__(key)            # support subclasses that define __missing__
  File "D:\soft\python36\lib\collections\__init__.py", line 877, in __missing__
    raise KeyError(key)
KeyError: 'dbname_sys'

During handling of the above exception, another exception occurred:

Traceback (most recent call last):
  File "E:\myproj\audit\common\config_reader.py", line 22, in get
    return self.conf.get(field,key)
  File "D:\soft\python36\lib\configparser.py", line 792, in get
    raise NoOptionError(option, section)
configparser.NoOptionError: No option 'dbname_sys' in section: 'mysql'
Thu, 18 Apr 2019 15:31:05 log.py[line:17] DEBUG 读取配置项发生了错误,mysql,dbname_sys
Thu, 18 Apr 2019 15:31:05 log.py[line:20] ERROR No option 'dbname_sys' in section: 'mysql'
Traceback (most recent call last):
  File "D:\soft\python36\lib\configparser.py", line 789, in get
    value = d[option]
  File "D:\soft\python36\lib\collections\__init__.py", line 885, in __getitem__
    return self.__missing__(key)            # support subclasses that define __missing__
  File "D:\soft\python36\lib\collections\__init__.py", line 877, in __missing__
    raise KeyError(key)
KeyError: 'dbname_sys'

During handling of the above exception, another exception occurred:

Traceback (most recent call last):
  File "E:\myproj\audit\common\config_reader.py", line 22, in get
    return self.conf.get(field,key)
  File "D:\soft\python36\lib\configparser.py", line 792, in get
    raise NoOptionError(option, section)
configparser.NoOptionError: No option 'dbname_sys' in section: 'mysql'
Thu, 18 Apr 2019 15:31:25 log.py[line:17] DEBUG 读取配置项发生了错误,mysql,dbname_sys
Thu, 18 Apr 2019 15:31:25 log.py[line:20] ERROR No option 'dbname_sys' in section: 'mysql'
Traceback (most recent call last):
  File "D:\soft\python36\lib\configparser.py", line 789, in get
    value = d[option]
  File "D:\soft\python36\lib\collections\__init__.py", line 885, in __getitem__
    return self.__missing__(key)            # support subclasses that define __missing__
  File "D:\soft\python36\lib\collections\__init__.py", line 877, in __missing__
    raise KeyError(key)
KeyError: 'dbname_sys'

During handling of the above exception, another exception occurred:

Traceback (most recent call last):
  File "E:\myproj\audit\common\config_reader.py", line 22, in get
    return self.conf.get(field,key)
  File "D:\soft\python36\lib\configparser.py", line 792, in get
    raise NoOptionError(option, section)
configparser.NoOptionError: No option 'dbname_sys' in section: 'mysql'
Thu, 18 Apr 2019 15:32:38 log.py[line:17] DEBUG 读取配置项发生了错误,mysql,dbname_sys
Thu, 18 Apr 2019 15:32:38 log.py[line:20] ERROR No option 'dbname_sys' in section: 'mysql'
Traceback (most recent call last):
  File "D:\soft\python36\lib\configparser.py", line 789, in get
    value = d[option]
  File "D:\soft\python36\lib\collections\__init__.py", line 885, in __getitem__
    return self.__missing__(key)            # support subclasses that define __missing__
  File "D:\soft\python36\lib\collections\__init__.py", line 877, in __missing__
    raise KeyError(key)
KeyError: 'dbname_sys'

During handling of the above exception, another exception occurred:

Traceback (most recent call last):
  File "E:\myproj\audit\common\config_reader.py", line 22, in get
    return self.conf.get(field,key)
  File "D:\soft\python36\lib\configparser.py", line 792, in get
    raise NoOptionError(option, section)
configparser.NoOptionError: No option 'dbname_sys' in section: 'mysql'
Thu, 18 Apr 2019 15:33:39 log.py[line:17] DEBUG 读取配置项发生了错误,mysql,dbname_sys
Thu, 18 Apr 2019 15:33:39 log.py[line:20] ERROR No option 'dbname_sys' in section: 'mysql'
Traceback (most recent call last):
  File "D:\soft\python36\lib\configparser.py", line 789, in get
    value = d[option]
  File "D:\soft\python36\lib\collections\__init__.py", line 885, in __getitem__
    return self.__missing__(key)            # support subclasses that define __missing__
  File "D:\soft\python36\lib\collections\__init__.py", line 877, in __missing__
    raise KeyError(key)
KeyError: 'dbname_sys'

During handling of the above exception, another exception occurred:

Traceback (most recent call last):
  File "E:\myproj\audit\common\config_reader.py", line 22, in get
    return self.conf.get(field,key)
  File "D:\soft\python36\lib\configparser.py", line 792, in get
    raise NoOptionError(option, section)
configparser.NoOptionError: No option 'dbname_sys' in section: 'mysql'
Thu, 18 Apr 2019 15:36:03 log.py[line:17] DEBUG 读取配置项发生了错误,mysql,dbname_sys
Thu, 18 Apr 2019 15:36:03 log.py[line:20] ERROR No option 'dbname_sys' in section: 'mysql'
Traceback (most recent call last):
  File "D:\soft\python36\lib\configparser.py", line 789, in get
    value = d[option]
  File "D:\soft\python36\lib\collections\__init__.py", line 885, in __getitem__
    return self.__missing__(key)            # support subclasses that define __missing__
  File "D:\soft\python36\lib\collections\__init__.py", line 877, in __missing__
    raise KeyError(key)
KeyError: 'dbname_sys'

During handling of the above exception, another exception occurred:

Traceback (most recent call last):
  File "E:\myproj\audit\common\config_reader.py", line 22, in get
    return self.conf.get(field,key)
  File "D:\soft\python36\lib\configparser.py", line 792, in get
    raise NoOptionError(option, section)
configparser.NoOptionError: No option 'dbname_sys' in section: 'mysql'
Thu, 18 Apr 2019 15:36:48 log.py[line:17] DEBUG 读取配置项发生了错误,mysql,dbname_sys
Thu, 18 Apr 2019 15:36:48 log.py[line:20] ERROR No option 'dbname_sys' in section: 'mysql'
Traceback (most recent call last):
  File "D:\soft\python36\lib\configparser.py", line 789, in get
    value = d[option]
  File "D:\soft\python36\lib\collections\__init__.py", line 885, in __getitem__
    return self.__missing__(key)            # support subclasses that define __missing__
  File "D:\soft\python36\lib\collections\__init__.py", line 877, in __missing__
    raise KeyError(key)
KeyError: 'dbname_sys'

During handling of the above exception, another exception occurred:

Traceback (most recent call last):
  File "E:\myproj\audit\common\config_reader.py", line 22, in get
    return self.conf.get(field,key)
  File "D:\soft\python36\lib\configparser.py", line 792, in get
    raise NoOptionError(option, section)
configparser.NoOptionError: No option 'dbname_sys' in section: 'mysql'
Thu, 18 Apr 2019 15:37:00 log.py[line:17] DEBUG 读取配置项发生了错误,mysql,dbname_sys
Thu, 18 Apr 2019 15:37:00 log.py[line:20] ERROR No option 'dbname_sys' in section: 'mysql'
Traceback (most recent call last):
  File "D:\soft\python36\lib\configparser.py", line 789, in get
    value = d[option]
  File "D:\soft\python36\lib\collections\__init__.py", line 885, in __getitem__
    return self.__missing__(key)            # support subclasses that define __missing__
  File "D:\soft\python36\lib\collections\__init__.py", line 877, in __missing__
    raise KeyError(key)
KeyError: 'dbname_sys'

During handling of the above exception, another exception occurred:

Traceback (most recent call last):
  File "E:\myproj\audit\common\config_reader.py", line 22, in get
    return self.conf.get(field,key)
  File "D:\soft\python36\lib\configparser.py", line 792, in get
    raise NoOptionError(option, section)
configparser.NoOptionError: No option 'dbname_sys' in section: 'mysql'
Thu, 18 Apr 2019 15:39:02 log.py[line:17] DEBUG 读取配置项发生了错误,mysql,dbname_sys
Thu, 18 Apr 2019 15:39:02 log.py[line:20] ERROR No option 'dbname_sys' in section: 'mysql'
Traceback (most recent call last):
  File "D:\soft\python36\lib\configparser.py", line 789, in get
    value = d[option]
  File "D:\soft\python36\lib\collections\__init__.py", line 885, in __getitem__
    return self.__missing__(key)            # support subclasses that define __missing__
  File "D:\soft\python36\lib\collections\__init__.py", line 877, in __missing__
    raise KeyError(key)
KeyError: 'dbname_sys'

During handling of the above exception, another exception occurred:

Traceback (most recent call last):
  File "E:\myproj\audit\common\config_reader.py", line 22, in get
    return self.conf.get(field,key)
  File "D:\soft\python36\lib\configparser.py", line 792, in get
    raise NoOptionError(option, section)
configparser.NoOptionError: No option 'dbname_sys' in section: 'mysql'
Thu, 18 Apr 2019 15:41:48 log.py[line:17] DEBUG 读取配置项发生了错误,mysql,dbname_sys
Thu, 18 Apr 2019 15:41:48 log.py[line:20] ERROR No option 'dbname_sys' in section: 'mysql'
Traceback (most recent call last):
  File "D:\soft\python36\lib\configparser.py", line 789, in get
    value = d[option]
  File "D:\soft\python36\lib\collections\__init__.py", line 885, in __getitem__
    return self.__missing__(key)            # support subclasses that define __missing__
  File "D:\soft\python36\lib\collections\__init__.py", line 877, in __missing__
    raise KeyError(key)
KeyError: 'dbname_sys'

During handling of the above exception, another exception occurred:

Traceback (most recent call last):
  File "E:\myproj\audit\common\config_reader.py", line 22, in get
    return self.conf.get(field,key)
  File "D:\soft\python36\lib\configparser.py", line 792, in get
    raise NoOptionError(option, section)
configparser.NoOptionError: No option 'dbname_sys' in section: 'mysql'
