Fri, 24 May 2019 14:24:26 log.py[line:17] DEBUG 读取配置项发生了错误,mysql,dbname_sys
Fri, 24 May 2019 14:24:26 log.py[line:20] ERROR No option 'dbname_sys' in section: 'mysql'
Traceback (most recent call last):
  File "D:\soft\python36\lib\configparser.py", line 789, in get
    value = d[option]
  File "D:\soft\python36\lib\collections\__init__.py", line 885, in __getitem__
    return self.__missing__(key)            # support subclasses that define __missing__
  File "D:\soft\python36\lib\collections\__init__.py", line 877, in __missing__
    raise KeyError(key)
KeyError: 'dbname_sys'

During handling of the above exception, another exception occurred:

Traceback (most recent call last):
  File "E:\myproj\audit_report\common\config_reader.py", line 22, in get
    return self.conf.get(field,key)
  File "D:\soft\python36\lib\configparser.py", line 792, in get
    raise NoOptionError(option, section)
configparser.NoOptionError: No option 'dbname_sys' in section: 'mysql'
Fri, 24 May 2019 14:24:26 connectionpool.py[line:205] DEBUG Starting new HTTP connection (1): 127.0.0.1:51116
Fri, 24 May 2019 14:24:27 connectionpool.py[line:393] DEBUG http://127.0.0.1:51116 "POST http://10.1.1.71:9999/syscenter/api/v1/currentUser HTTP/1.1" 200 None
Fri, 24 May 2019 14:24:27 log.py[line:17] DEBUG 读取配置项发生了错误,api,审方工作统计按机构统计
Fri, 24 May 2019 14:24:27 log.py[line:20] ERROR No option '审方工作统计按机构统计' in section: 'api'
Traceback (most recent call last):
  File "D:\soft\python36\lib\configparser.py", line 789, in get
    value = d[option]
  File "D:\soft\python36\lib\collections\__init__.py", line 885, in __getitem__
    return self.__missing__(key)            # support subclasses that define __missing__
  File "D:\soft\python36\lib\collections\__init__.py", line 877, in __missing__
    raise KeyError(key)
KeyError: '审方工作统计按机构统计'

During handling of the above exception, another exception occurred:

Traceback (most recent call last):
  File "E:\myproj\audit_report\common\config_reader.py", line 22, in get
    return self.conf.get(field,key)
  File "D:\soft\python36\lib\configparser.py", line 792, in get
    raise NoOptionError(option, section)
configparser.NoOptionError: No option '审方工作统计按机构统计' in section: 'api'
Fri, 24 May 2019 14:24:27 connectionpool.py[line:393] DEBUG http://127.0.0.1:51116 "POST http://10.1.1.71:9999/auditcenter/None HTTP/1.1" 405 173
Fri, 24 May 2019 14:38:58 log.py[line:17] DEBUG 读取配置项发生了错误,mysql,dbname_sys
Fri, 24 May 2019 14:38:58 log.py[line:20] ERROR No option 'dbname_sys' in section: 'mysql'
Traceback (most recent call last):
  File "D:\soft\python36\lib\configparser.py", line 789, in get
    value = d[option]
  File "D:\soft\python36\lib\collections\__init__.py", line 885, in __getitem__
    return self.__missing__(key)            # support subclasses that define __missing__
  File "D:\soft\python36\lib\collections\__init__.py", line 877, in __missing__
    raise KeyError(key)
KeyError: 'dbname_sys'

During handling of the above exception, another exception occurred:

Traceback (most recent call last):
  File "E:\myproj\audit_report\common\config_reader.py", line 22, in get
    return self.conf.get(field,key)
  File "D:\soft\python36\lib\configparser.py", line 792, in get
    raise NoOptionError(option, section)
configparser.NoOptionError: No option 'dbname_sys' in section: 'mysql'
Fri, 24 May 2019 14:40:04 log.py[line:17] DEBUG 读取配置项发生了错误,mysql,dbname_sys
Fri, 24 May 2019 14:40:04 log.py[line:20] ERROR No option 'dbname_sys' in section: 'mysql'
Traceback (most recent call last):
  File "D:\soft\python36\lib\configparser.py", line 789, in get
    value = d[option]
  File "D:\soft\python36\lib\collections\__init__.py", line 885, in __getitem__
    return self.__missing__(key)            # support subclasses that define __missing__
  File "D:\soft\python36\lib\collections\__init__.py", line 877, in __missing__
    raise KeyError(key)
KeyError: 'dbname_sys'

During handling of the above exception, another exception occurred:

Traceback (most recent call last):
  File "E:\myproj\audit_report\common\config_reader.py", line 22, in get
    return self.conf.get(field,key)
  File "D:\soft\python36\lib\configparser.py", line 792, in get
    raise NoOptionError(option, section)
configparser.NoOptionError: No option 'dbname_sys' in section: 'mysql'
Fri, 24 May 2019 14:41:50 log.py[line:17] DEBUG 读取配置项发生了错误,mysql,dbname_sys
Fri, 24 May 2019 14:41:50 log.py[line:20] ERROR No option 'dbname_sys' in section: 'mysql'
Traceback (most recent call last):
  File "D:\soft\python36\lib\configparser.py", line 789, in get
    value = d[option]
  File "D:\soft\python36\lib\collections\__init__.py", line 885, in __getitem__
    return self.__missing__(key)            # support subclasses that define __missing__
  File "D:\soft\python36\lib\collections\__init__.py", line 877, in __missing__
    raise KeyError(key)
KeyError: 'dbname_sys'

During handling of the above exception, another exception occurred:

Traceback (most recent call last):
  File "E:\myproj\audit_report\common\config_reader.py", line 22, in get
    return self.conf.get(field,key)
  File "D:\soft\python36\lib\configparser.py", line 792, in get
    raise NoOptionError(option, section)
configparser.NoOptionError: No option 'dbname_sys' in section: 'mysql'
Fri, 24 May 2019 14:41:50 connectionpool.py[line:205] DEBUG Starting new HTTP connection (1): 127.0.0.1:51116
Fri, 24 May 2019 14:41:50 connectionpool.py[line:393] DEBUG http://127.0.0.1:51116 "POST http://10.1.1.71:9999/syscenter/api/v1/currentUser HTTP/1.1" 200 None
Fri, 24 May 2019 14:41:50 connectionpool.py[line:393] DEBUG http://127.0.0.1:51116 "POST http://10.1.1.71:9999/auditcenter//api/v1/sfReport/workReportByOrg HTTP/1.1" 200 None
Fri, 24 May 2019 15:02:22 log.py[line:17] DEBUG 读取配置项发生了错误,mysql,dbname_sys
Fri, 24 May 2019 15:02:22 log.py[line:20] ERROR No option 'dbname_sys' in section: 'mysql'
Traceback (most recent call last):
  File "D:\soft\python36\lib\configparser.py", line 789, in get
    value = d[option]
  File "D:\soft\python36\lib\collections\__init__.py", line 885, in __getitem__
    return self.__missing__(key)            # support subclasses that define __missing__
  File "D:\soft\python36\lib\collections\__init__.py", line 877, in __missing__
    raise KeyError(key)
KeyError: 'dbname_sys'

During handling of the above exception, another exception occurred:

Traceback (most recent call last):
  File "E:\myproj\audit_report\common\config_reader.py", line 22, in get
    return self.conf.get(field,key)
  File "D:\soft\python36\lib\configparser.py", line 792, in get
    raise NoOptionError(option, section)
configparser.NoOptionError: No option 'dbname_sys' in section: 'mysql'
Fri, 24 May 2019 15:02:23 connectionpool.py[line:205] DEBUG Starting new HTTP connection (1): 127.0.0.1:51116
Fri, 24 May 2019 15:02:23 connectionpool.py[line:393] DEBUG http://127.0.0.1:51116 "POST http://10.1.1.71:9999/syscenter/api/v1/currentUser HTTP/1.1" 200 None
Fri, 24 May 2019 15:02:23 connectionpool.py[line:393] DEBUG http://127.0.0.1:51116 "POST http://10.1.1.71:9999/auditcenter//api/v1/sfReport/workReportByOrg HTTP/1.1" 200 None
Fri, 24 May 2019 15:49:22 log.py[line:17] DEBUG 读取配置项发生了错误,mysql,dbname_sys
Fri, 24 May 2019 15:49:22 log.py[line:20] ERROR No option 'dbname_sys' in section: 'mysql'
Traceback (most recent call last):
  File "D:\soft\python36\lib\configparser.py", line 789, in get
    value = d[option]
  File "D:\soft\python36\lib\collections\__init__.py", line 885, in __getitem__
    return self.__missing__(key)            # support subclasses that define __missing__
  File "D:\soft\python36\lib\collections\__init__.py", line 877, in __missing__
    raise KeyError(key)
KeyError: 'dbname_sys'

During handling of the above exception, another exception occurred:

Traceback (most recent call last):
  File "E:\myproj\audit_report\common\config_reader.py", line 22, in get
    return self.conf.get(field,key)
  File "D:\soft\python36\lib\configparser.py", line 792, in get
    raise NoOptionError(option, section)
configparser.NoOptionError: No option 'dbname_sys' in section: 'mysql'
Fri, 24 May 2019 15:49:23 connectionpool.py[line:205] DEBUG Starting new HTTP connection (1): 10.1.1.71:9999
Fri, 24 May 2019 15:49:23 connectionpool.py[line:393] DEBUG http://10.1.1.71:9999 "POST /syscenter/api/v1/currentUser HTTP/1.1" 200 None
Fri, 24 May 2019 15:49:23 connectionpool.py[line:393] DEBUG http://10.1.1.71:9999 "POST /auditcenter//api/v1/sfReport/workReportByOrg HTTP/1.1" 200 None
Fri, 24 May 2019 15:50:52 log.py[line:17] DEBUG 读取配置项发生了错误,mysql,dbname_sys
Fri, 24 May 2019 15:50:52 log.py[line:20] ERROR No option 'dbname_sys' in section: 'mysql'
Traceback (most recent call last):
  File "D:\soft\python36\lib\configparser.py", line 789, in get
    value = d[option]
  File "D:\soft\python36\lib\collections\__init__.py", line 885, in __getitem__
    return self.__missing__(key)            # support subclasses that define __missing__
  File "D:\soft\python36\lib\collections\__init__.py", line 877, in __missing__
    raise KeyError(key)
KeyError: 'dbname_sys'

During handling of the above exception, another exception occurred:

Traceback (most recent call last):
  File "E:\myproj\audit_report\common\config_reader.py", line 22, in get
    return self.conf.get(field,key)
  File "D:\soft\python36\lib\configparser.py", line 792, in get
    raise NoOptionError(option, section)
configparser.NoOptionError: No option 'dbname_sys' in section: 'mysql'
Fri, 24 May 2019 15:50:52 connectionpool.py[line:205] DEBUG Starting new HTTP connection (1): 10.1.1.71:9999
Fri, 24 May 2019 15:50:52 connectionpool.py[line:393] DEBUG http://10.1.1.71:9999 "POST /syscenter/api/v1/currentUser HTTP/1.1" 200 None
Fri, 24 May 2019 15:50:52 connectionpool.py[line:393] DEBUG http://10.1.1.71:9999 "POST /auditcenter//api/v1/sfReport/workReportByOrg HTTP/1.1" 200 None
Fri, 24 May 2019 16:04:25 log.py[line:17] DEBUG 读取配置项发生了错误,mysql,dbname_sys
Fri, 24 May 2019 16:04:25 log.py[line:20] ERROR No option 'dbname_sys' in section: 'mysql'
Traceback (most recent call last):
  File "D:\soft\python36\lib\configparser.py", line 789, in get
    value = d[option]
  File "D:\soft\python36\lib\collections\__init__.py", line 885, in __getitem__
    return self.__missing__(key)            # support subclasses that define __missing__
  File "D:\soft\python36\lib\collections\__init__.py", line 877, in __missing__
    raise KeyError(key)
KeyError: 'dbname_sys'

During handling of the above exception, another exception occurred:

Traceback (most recent call last):
  File "E:\myproj\audit_report\common\config_reader.py", line 22, in get
    return self.conf.get(field,key)
  File "D:\soft\python36\lib\configparser.py", line 792, in get
    raise NoOptionError(option, section)
configparser.NoOptionError: No option 'dbname_sys' in section: 'mysql'
Fri, 24 May 2019 16:04:35 log.py[line:17] DEBUG 读取配置项发生了错误,mysql,dbname_sys
Fri, 24 May 2019 16:04:35 log.py[line:20] ERROR No option 'dbname_sys' in section: 'mysql'
Traceback (most recent call last):
  File "D:\soft\python36\lib\configparser.py", line 789, in get
    value = d[option]
  File "D:\soft\python36\lib\collections\__init__.py", line 885, in __getitem__
    return self.__missing__(key)            # support subclasses that define __missing__
  File "D:\soft\python36\lib\collections\__init__.py", line 877, in __missing__
    raise KeyError(key)
KeyError: 'dbname_sys'

During handling of the above exception, another exception occurred:

Traceback (most recent call last):
  File "E:\myproj\audit_report\common\config_reader.py", line 22, in get
    return self.conf.get(field,key)
  File "D:\soft\python36\lib\configparser.py", line 792, in get
    raise NoOptionError(option, section)
configparser.NoOptionError: No option 'dbname_sys' in section: 'mysql'
Fri, 24 May 2019 16:04:35 connectionpool.py[line:205] DEBUG Starting new HTTP connection (1): 10.1.1.71:9999
Fri, 24 May 2019 16:04:35 connectionpool.py[line:393] DEBUG http://10.1.1.71:9999 "POST /syscenter/api/v1/currentUser HTTP/1.1" 200 None
Fri, 24 May 2019 16:04:35 connectionpool.py[line:393] DEBUG http://10.1.1.71:9999 "POST /auditcenter//api/v1/sfReport/workReportByOrg HTTP/1.1" 200 None
Fri, 24 May 2019 16:12:25 log.py[line:17] DEBUG 读取配置项发生了错误,mysql,dbname_sys
Fri, 24 May 2019 16:12:25 log.py[line:20] ERROR No option 'dbname_sys' in section: 'mysql'
Traceback (most recent call last):
  File "D:\soft\python36\lib\configparser.py", line 789, in get
    value = d[option]
  File "D:\soft\python36\lib\collections\__init__.py", line 885, in __getitem__
    return self.__missing__(key)            # support subclasses that define __missing__
  File "D:\soft\python36\lib\collections\__init__.py", line 877, in __missing__
    raise KeyError(key)
KeyError: 'dbname_sys'

During handling of the above exception, another exception occurred:

Traceback (most recent call last):
  File "E:\myproj\audit_report\common\config_reader.py", line 22, in get
    return self.conf.get(field,key)
  File "D:\soft\python36\lib\configparser.py", line 792, in get
    raise NoOptionError(option, section)
configparser.NoOptionError: No option 'dbname_sys' in section: 'mysql'
Fri, 24 May 2019 16:12:25 connectionpool.py[line:205] DEBUG Starting new HTTP connection (1): 10.1.1.71:9999
Fri, 24 May 2019 16:12:25 connectionpool.py[line:393] DEBUG http://10.1.1.71:9999 "POST /syscenter/api/v1/currentUser HTTP/1.1" 200 None
Fri, 24 May 2019 16:12:25 connectionpool.py[line:393] DEBUG http://10.1.1.71:9999 "POST /auditcenter//api/v1/sfReport/workReportByOrg HTTP/1.1" 200 None
Fri, 24 May 2019 16:17:39 log.py[line:17] DEBUG 读取配置项发生了错误,mysql,dbname_sys
Fri, 24 May 2019 16:17:39 log.py[line:20] ERROR No option 'dbname_sys' in section: 'mysql'
Traceback (most recent call last):
  File "D:\soft\python36\lib\configparser.py", line 789, in get
    value = d[option]
  File "D:\soft\python36\lib\collections\__init__.py", line 885, in __getitem__
    return self.__missing__(key)            # support subclasses that define __missing__
  File "D:\soft\python36\lib\collections\__init__.py", line 877, in __missing__
    raise KeyError(key)
KeyError: 'dbname_sys'

During handling of the above exception, another exception occurred:

Traceback (most recent call last):
  File "E:\myproj\audit_report\common\config_reader.py", line 22, in get
    return self.conf.get(field,key)
  File "D:\soft\python36\lib\configparser.py", line 792, in get
    raise NoOptionError(option, section)
configparser.NoOptionError: No option 'dbname_sys' in section: 'mysql'
Fri, 24 May 2019 16:17:39 connectionpool.py[line:205] DEBUG Starting new HTTP connection (1): 10.1.1.71:9999
Fri, 24 May 2019 16:17:39 connectionpool.py[line:393] DEBUG http://10.1.1.71:9999 "POST /syscenter/api/v1/currentUser HTTP/1.1" 200 None
Fri, 24 May 2019 16:17:39 connectionpool.py[line:393] DEBUG http://10.1.1.71:9999 "POST /auditcenter//api/v1/sfReport/workReportByOrg HTTP/1.1" 200 None
